Workbook

Sheet Cover
B3: ASML Holding N.V.
B5: Discounted Cash Flow Valuation
B8: Ticker | C8: ASML (Euronext Amsterdam) / ASML (Nasdaq)
B9: Valuation date | C9: =Assumptions!$C$5 -> 46302
B10: Currency | C10: EUR, millions unless stated
B11: Analyst | C11: Ates Parilti
B12: Active scenario | C12: =Assumptions!$C$9 -> Base
B13: DCF price (blended) | C13: =DCF!$E$35 -> 935.30172
B14: DCF Gordon / Exit | C14: =TEXT(DCF!$C$35,"€#,##0")&" / "&TEXT(DCF!$D$35,"€#,##0") -> €759 / €1,112
B15: Trading comps (peer range) | C15: =TEXT(Comps!$E$24,"€#,##0")&" - "&TEXT(Comps!$G$24,"€#,##0") -> €1,251 - €1,690
B16: Current share price | C16: =Assumptions!$C$16 -> 1611.4
B17: Upside / (downside), blended DCF | C17: =DCF!$E$37 -> -0.41957198
B18: Model checks | C18: =Checks!$C$4 -> ALL PASS
B20: Company
C21: ASML designs and builds the lithography systems that print circuit patterns onto silicon wafers. It is the sole supplier of EUV lithography, which every leading-edge logic and DRAM fab depends on. Revenue comes from system sales (EUV, DUV, metrology & inspection) and a growing, recurring installed-base business (service and upgrades).
B23: How to use
B24: 1. Change inputs only on Assumptions (blue on yellow). The scenario selector switches Bear / Base / Bull.
B25: 2. Revenue Build, Forecast, WACC, DCF, Sensitivity, Scenarios, Comps valuation and Dashboard are formulas.
B26: 3. Checks tests the model; the status is shown above and on the Dashboard.
B27: Colour code: blue = hard-coded input; black = formula; green = link to another sheet; grey header = historical; blue header = forecast; light blue = fade.
B29: Sources
B30: [S1] ASML Form 20-F / Annual Report 2025 (US GAAP), filed 25 Feb 2026, incl. XBRL data | C30: https://www.sec.gov/Archives/edgar/data/937966/000162828026011378/asml-20251231.htm
B31: [S2] SEC EDGAR XBRL company facts for ASML (20-F filings FY2020-FY2025) | C31: https://data.sec.gov/api/xbrl/companyfacts/CIK0000937966.json
B32: [S3] ASML Financial Statements US GAAP Q4 2025 (Form 6-K, 28 Jan 2026) | C32: https://www.sec.gov/Archives/edgar/data/937966/000162828026003701/
B33: [S4] ASML Q2 2026 press release and Financial Statements US GAAP (Form 6-K, 15 Jul 2026) | C33: https://www.sec.gov/Archives/edgar/data/0000937966/000162828026048235/pressreleasefinancialresul.htm
B34: [S5] ASML (Euronext Amsterdam: ASML) closing price 7 Oct 2026, via stockanalysis.com | C34: https://stockanalysis.com/quote/ams/ASML/history/
B35: [S6] Germany 10Y Bund yield, 7 Oct 2026, Trading Economics | C35: https://tradingeconomics.com/germany/government-bond-yield
B36: [S7] A. Damodaran, Country risk premiums (Jan 2026): Netherlands total ERP 4.23%, CRP 0% | C36: https://pages.stern.nyu.edu/~adamodar/New_Home_Page/datafile/ctryprem.html
B37: [S8] A. Damodaran, Betas by sector (Jan 2026): Semiconductor Equip unlevered beta corrected for cash 1.39 | C37: https://pages.stern.nyu.edu/~adamodar/New_Home_Page/datafile/Betas.html
B38: [S9] Yahoo Finance monthly and daily prices: ASML.AS and STOXX Europe 600 (^STOXX); regression beta, 52-week range, year-end prices | C38: https://finance.yahoo.com/quote/ASML.AS/history/
B39: [S10] ASML 2024 Investor Day: 2030 revenue opportunity EUR 44-60bn, gross margin 56-60% | C39: https://investor.asml.com/news-releases/news-release-details/asml-provides-updated-view-market-opportunities-2024-investor-day-meeting
B40: [S11] ASML Q4 2025 press release: 2025 sales EUR 32.7bn, backlog EUR 38.8bn | C40: https://www.asml.com/en/news/press-releases/2026/q4-2025-financial-results
B41: [S12] Peer trading data (price, market cap, EV, TTM EBITDA, forward P/E, margins) for AMAT, LRCX, KLAC, Tokyo Electron, ASML, 7-8 Oct 2026, stockanalysis.com | C41: https://stockanalysis.com/stocks/amat/statistics/
B43: For educational purposes only. Not investment advice.

Sheet Assumptions
B1: Assumptions
B2: All model inputs live here. Blue on yellow = hard-coded input; black = formula; green fill = live (selected scenario). EUR millions unless stated.
B4: General | J4: Type | K4: Source / note
B5: Valuation date | C5: 46302 | K5: Pricing date for market data
B6: Latest balance sheet date | C6: 46201 | J6: REPORTED | K6: [S4] Q2 2026 balance sheet; cash flows after this date are valued
B7: FY2026 year end | C7: 46387 | K7: ASML fiscal year = calendar year
B8: Scenario selector (1 Bear, 2 Base, 3 Bull) | C8: 2 | J8: INPUT | K8: Drives the live model (Revenue Build, Forecast, DCF, Sensitivity)
B9: Active scenario | C9: =CHOOSE(Assumptions!$C$8,"Bear","Base","Bull") -> Base
B10: Method switches | J10: Type | K10: Source / note
B11: Mid-year discounting (1 = on, 0 = off) | C11: 1 | J11: INPUT | K11: Cash flows arrive evenly through each year (standard banking convention)
B12: Weight of Gordon Growth in blended price | C12: 0.5 | J12: ASSUMPTION | K12: Blended DCF price = weight x Gordon + (1 - weight) x Exit Multiple
B13: Fade period length (years) | C13: 5 | J13: ASSUMPTION | K13: FY31-FY35: growth steps linearly from the FY30 rate to terminal g; margins, capex, NWC held at FY30
B15: Market data & latest balance sheet | J15: Type | K15: Source / note
B16: Current share price (EUR) | C16: 1611.4 | J16: MARKET | K16: [S5] Closing price Euronext Amsterdam, 7 Oct 2026 (EUR)
B17: Diluted shares outstanding (m) | C17: 384.9 | J17: REPORTED | K17: [S4] Diluted weighted avg. shares Q2 2026 (m)
B18: Cash & short-term investments | C18: 7581.5 | J18: REPORTED | K18: [S4] Cash 6,671.9 + short-term investments 909.6 at 28 Jun 2026
B19: Total debt (bonds + commercial paper) | C19: 3697.7 | J19: DERIVED | K19: [S1/S4] FY25 borrowings 4,390.9 (LT 2,709.0 + current 1,681.9 incl. ECP) less H1-26 repayments 693.2
B20: Non-operating investments | C20: 2310.7 | J20: REPORTED | K20: [S4] Equity investments 1,324.9 + equity-method investments 985.8 at 28 Jun 2026
B21: H1-2026 actual unlevered FCF | C21: -1290.9 | J21: DERIVED | K21: [S4] H1-26 CFO (482.5) - PP&E capex 701.8 - intangibles 106.6; already reflected in 28 Jun cash
B22: 52-week low (EUR) | C22: 813.9 | J22: MARKET | K22: [S9] 52-week low close, Euronext Amsterdam (Oct-25 to Oct-26)
B23: 52-week high (EUR) | C23: 1721.4 | J23: MARKET | K23: [S9] 52-week high close, Euronext Amsterdam (Oct-25 to Oct-26)
B25: LTM EBITDA inputs (for trading comps) | J25: Type | K25: Source / note
B26: H1-2026 income from operations | C26: 6613.9 | J26: REPORTED | K26: [S4] Six months to 28 Jun 2026
B27: H1-2026 depreciation & amortization | C27: 506.3 | J27: REPORTED | K27: [S4] Cash flow statement
B28: H1-2025 income from operations | C28: 5402 | J28: REPORTED | K28: [S4] Six months to 29 Jun 2025
B29: H1-2025 depreciation & amortization | C29: 496.2 | J29: REPORTED | K29: [S4] Cash flow statement
B31: Cost of capital inputs | J31: Type | K31: Source / note
B32: Risk-free rate (10Y Bund) | C32: 0.0351 | J32: MARKET | K32: [S6] German 10Y Bund yield 7 Oct 2026; EUR risk-free matching EUR cash flows
B33: Equity risk premium | C33: 0.0423 | J33: MARKET | K33: [S7] Damodaran implied mature-market ERP, Netherlands CRP = 0
B34: Regression beta vs STOXX Europe 600 (5Y monthly) | C34: 1.79 | J34: DERIVED | K34: [S9] Regression vs STOXX Europe 600, 60 monthly returns Oct-21 to Sep-26 (R² 0.33, std. error ~0.34): too noisy to use alone
B35: Industry unlevered beta (semi equipment) | C35: 1.39 | J35: MARKET | K35: [S8] Semiconductor equipment unlevered beta, cash-corrected
B36: Weight on regression beta | C36: 0 | J36: ASSUMPTION | K36: 0% weight on regression: bottom-up industry beta is used (standard practice when the regression is imprecise)
B37: Credit spread over risk-free (A1/A+) | C37: 0.006 | J37: ASSUMPTION | K37: [S1] Credit spread for A1/A+ (Moody's/Fitch) EUR corporate issuer
B38: Marginal tax rate (debt tax shield) | C38: 0.258 | J38: ASSUMPTION | K38: Dutch statutory CIT rate 25.8% for the interest tax shield
B40: FY2025 revenue mix (base year for the revenue build) | J40: Type | K40: Source / note
B41: EUV low-NA (NXE) systems recognised | C41: 44 | J41: REPORTED | K41: [S1] Note 2, net system sales per technology
B42: EUV low-NA (NXE) sales | C42: 10445.8 | J42: REPORTED | K42: [S1]
B43: EUV High-NA (EXE) systems recognised | C43: 4 | J43: REPORTED | K43: [S1] R&D systems at customers
B44: EUV High-NA (EXE) sales | C44: 1156.9 | J44: REPORTED | K44: [S1]
B45: DUV immersion (ArFi) systems | C45: 131 | J45: REPORTED | K45: [S1]
...

Sheet Historical
B1: Historical Financials
B2: Reported US GAAP figures (blue) from ASML 20-F filings via SEC XBRL [S1, S2, S3]; ratios and FCF are calculated (black). EUR millions.
B4: EUR m, fiscal year ending 31 Dec | C4: FY20A (ref) | D4: FY21A | E4: FY22A | F4: FY23A | G4: FY24A | H4: FY25A | I4: Type | J4: Source / definition
B5: Reported (US GAAP) and market
B6: Total net sales | C6: 13978.5 | D6: 18611 | E6: 21173.4 | F6: 27558.5 | G6: 28262.9 | H6: 32667.3 | I6: REPORTED | J6: [S2] XBRL 20-F
B7: Cost of sales | D7: 8802 | E7: 10473.3 | F7: 13422.4 | G7: 13770.9 | H7: 15409.3 | I7: REPORTED | J7: [S2] XBRL 20-F
B8: Gross profit | D8: 9809 | E8: 10700.1 | F8: 14136.1 | G8: 14492 | H8: 17258 | I8: REPORTED | J8: [S2] XBRL 20-F
B9: Research & development | D9: 2547 | E9: 3253.5 | F9: 3980.6 | G9: 4303.7 | H9: 4698.8 | I9: REPORTED | J9: [S2] XBRL 20-F
B10: Selling, general & administrative | D10: 725.6 | E10: 945.9 | F10: 1113.2 | G10: 1165.7 | H10: 1257.8 | I10: REPORTED | J10: [S2] XBRL 20-F
B11: Income from operations (EBIT) | D11: 6750.1 | E11: 6500.7 | F11: 9042.3 | G11: 9022.6 | H11: 11301.4 | I11: REPORTED | J11: [S2] XBRL 20-F
B12: Depreciation & amortization (cash flow statement) | D12: 471 | E12: 583.6 | F12: 739.8 | G12: 918.6 | H12: 1025.9 | I12: REPORTED | J12: [S2] XBRL 20-F
B13: Income before income taxes | D13: 6705.5 | E13: 6456.1 | F13: 9083.5 | G13: 9042.4 | H13: 11406.1 | I13: REPORTED | J13: [S2] XBRL 20-F
B14: Income tax expense | D14: 1021.4 | E14: 969.9 | F14: 1435.8 | G14: 1680.6 | H14: 2013.4 | I14: REPORTED | J14: [S2] XBRL 20-F
B15: Net income | D15: 5883.2 | E15: 5624.2 | F15: 7839 | G15: 7571.6 | H15: 9609.4 | I15: REPORTED | J15: [S2] XBRL 20-F
B16: Purchase of PP&E | D16: 900.7 | E16: 1281.8 | F16: 2155.6 | G16: 2067.2 | H16: 1573.6 | I16: REPORTED | J16: [S2] XBRL 20-F
B17: Purchase of intangible assets | D17: 39.6 | E17: 37.5 | F17: 40.6 | G17: 15.9 | H17: 57.6 | I17: REPORTED | J17: [S2] XBRL 20-F
B18: Net cash from operating activities | D18: 10845.8 | E18: 8486.8 | F18: 5443.4 | G18: 11166.2 | H18: 12658.5 | I18: REPORTED | J18: [S2] XBRL 20-F
B19: Cash & cash equivalents | C19: 6049.4 | D19: 6951.8 | E19: 7268.3 | F19: 7004.7 | G19: 12735.9 | H19: 12916 | I19: REPORTED | J19: [S2] XBRL 20-F
B20: Short-term investments | C20: 1302.2 | D20: 638.5 | E20: 107.7 | F20: 5.4 | G20: 5.4 | H20: 405.9 | I20: REPORTED | J20: [S2] XBRL 20-F
B21: Total current assets | C21: 15930 | D21: 18190.2 | E21: 23064.9 | F21: 24393.9 | G21: 30737.4 | H21: 30616.1 | I21: REPORTED | J21: [S2] XBRL 20-F
B22: Loans receivable, current (non-operating) | C22: 0 | D22: 0 | E22: 0 | F22: 0 | G22: 0 | H22: 266.1 | I22: REPORTED | J22: [S2] XBRL 20-F; new line in FY25 [S3]
B23: Total current liabilities | C23: 6603.5 | D23: 12298 | E23: 17983.6 | F23: 16274.7 | G23: 20051.4 | H23: 24263.9 | I23: REPORTED | J23: [S2] XBRL 20-F
B24: Current debt incl. commercial paper | C24: 15.4 | D24: 509.1 | E24: 746.2 | F24: 0.1 | G24: 1010.3 | H24: 1681.9 | I24: REPORTED | J24: [S2] XBRL 20-F; FY25 current debt = bonds 990.2 + ECP 691.7 [S1]
B25: Long-term debt | D25: 4075 | E25: 3514.2 | F25: 4631.5 | G25: 3677.3 | H25: 2709 | I25: REPORTED | J25: [S2] XBRL 20-F
B26: Contract liabilities, non-current | C26: 1639.9 | D26: 3225.7 | E26: 5269.9 | F26: 4825.5 | G26: 5625.4 | H26: 3366.3 | I26: REPORTED | J26: [S2] XBRL 20-F
B27: Diluted weighted avg. shares (m) | D27: 410.4 | E27: 398 | F27: 394.1 | G27: 393.6 | H27: 388.9 | I27: REPORTED | J27: [S2] XBRL 20-F
B28: Year-end share price, Euronext (EUR) | D28: 706.7 | E28: 503.8 | F28: 681.7 | G28: 678.7 | H28: 921.4 | I28: MARKET | J28: [S9] Yahoo Finance
B30: Calculated
B31: Revenue growth % | D31: =D6/C6-1 -> 0.3314018 | E31: =E6/D6-1 -> 0.13768202 | F31: =F6/E6-1 -> 0.30156234 | G31: =G6/F6-1 -> 0.025560172 | H31: =H6/G6-1 -> 0.1558368 | I31: CALCULATED | J31: Revenue / prior-year revenue - 1
B32: Gross margin % | D32: =D8/D6 -> 0.52705389 | E32: =E8/E6 -> 0.50535578 | F32: =F8/F6 -> 0.51294882 | G32: =G8/G6 -> 0.51275701 | H32: =H8/H6 -> 0.52829588 | I32: CALCULATED | J32: Gross profit / revenue
B33: EBITDA | D33: =D11+D12 -> 7221.1 | E33: =E11+E12 -> 7084.3 | F33: =F11+F12 -> 9782.1 | G33: =G11+G12 -> 9941.2 | H33: =H11+H12 -> 12327.3 | I33: CALCULATED | J33: EBIT + D&A
B34: EBITDA margin % | D34: =D33/D6 -> 0.38800172 | E34: =E33/E6 -> 0.3345849 | F34: =F33/F6 -> 0.35495764 | G34: =G33/G6 -> 0.35174027 | H34: =H33/H6 -> 0.37735901 | I34: CALCULATED | J34: EBITDA / revenue
B35: EBIT margin % | D35: =D11/D6 -> 0.36269411 | E35: =E11/E6 -> 0.30702202 | F35: =F11/F6 -> 0.32811292 | G35: =G11/G6 -> 0.31923829 | H35: =H11/H6 -> 0.34595452 | I35: CALCULATED | J35: EBIT / revenue
B36: D&A % revenue | D36: =D12/D6 -> 0.025307614 | E36: =E12/E6 -> 0.027562886 | F36: =F12/F6 -> 0.026844712 | G36: =G12/G6 -> 0.032501973 | H36: =H12/H6 -> 0.031404493 | I36: CALCULATED | J36: D&A / revenue
B37: R&D % revenue | D37: =D9/D6 -> 0.13685455 | E37: =E9/E6 -> 0.15365978 | F37: =F9/F6 -> 0.14444182 | G37: =G9/G6 -> 0.15227383 | H37: =H9/H6 -> 0.14383803 | I37: CALCULATED | J37: R&D / revenue
B38: Effective tax rate | D38: =D14/D13 -> 0.15232272 | E38: =E14/E13 -> 0.15023002 | F38: =F14/F13 -> 0.15806682 | G38: =G14/G13 -> 0.18585774 | H38: =H14/H13 -> 0.17651958 | I38: CALCULATED | J38: Income tax expense / income before taxes
B39: Taxes on EBIT | D39: =D11*D38 -> 1028.1936 | E39: =E11*E38 -> 976.60026 | F39: =F11*F38 -> 1429.2876 | G39: =G11*G38 -> 1676.92 | H39: =H11*H38 -> 1994.9184 | I39: CALCULATED | J39: EBIT x effective tax rate (unlevered taxes)
B40: NOPAT | D40: =D11-D39 -> 5721.9064 | E40: =E11-E39 -> 5524.0997 | F40: =F11-F39 -> 7613.0124 | G40: =G11-G39 -> 7345.68 | H40: =H11-H39 -> 9306.4816 | I40: CALCULATED | J40: EBIT - taxes on EBIT
B41: Total CapEx (PP&E + intangibles) | D41: =D16+D17 -> 940.3 | E41: =E16+E17 -> 1319.3 | F41: =F16+F17 -> 2196.2 | G41: =G16+G17 -> 2083.1 | H41: =H16+H17 -> 1631.2 | I41: CALCULATED
B42: CapEx % revenue | D42: =D41/D6 -> 0.050523884 | E42: =E41/E6 -> 0.062309313 | F42: =F41/F6 -> 0.079692291 | G42: =G41/G6 -> 0.073704397 | H42: =H41/H6 -> 0.049933726 | I42: CALCULATED
...

Sheet Revenue Build
B1: Revenue Build
B2: Live scenario. System revenue = units x average selling price (ASP); other segments grow from their FY25 base. EUR millions.
B4: EUR m | C4: FY25A | D4: FY26E | E4: FY27E | F4: FY28E | G4: FY29E | H4: FY30E
B5: Scenario: | C5: =Assumptions!$C$9 -> Base
B7: EUV low-NA (NXE)
B8: Systems | C8: =Assumptions!$C$41 -> 44 | D8: =Assumptions!E61 -> 65 | E8: =Assumptions!F61 -> 75 | F8: =Assumptions!G61 -> 82 | G8: =Assumptions!H61 -> 86 | H8: =Assumptions!I61 -> 88
B9: ASP (EUR m) | C9: =C10/C8 -> 237.40455 | D9: =Assumptions!E66 -> 255 | E9: =Assumptions!F66 -> 260 | F9: =Assumptions!G66 -> 265 | G9: =Assumptions!H66 -> 270 | H9: =Assumptions!I66 -> 275 | J9: FY25A ASP = reported sales / units
B10: Revenue | C10: =Assumptions!$C$42 -> 10445.8 | D10: =D8*D9 -> 16575 | E10: =E8*E9 -> 19500 | F10: =F8*F9 -> 21730 | G10: =G8*G9 -> 23220 | H10: =H8*H9 -> 24200
B12: EUV High-NA (EXE)
B13: Systems | C13: =Assumptions!$C$43 -> 4 | D13: =Assumptions!E71 -> 8 | E13: =Assumptions!F71 -> 10 | F13: =Assumptions!G71 -> 14 | G13: =Assumptions!H71 -> 18 | H13: =Assumptions!I71 -> 22
B14: ASP (EUR m) | C14: =C15/C13 -> 289.225 | D14: =Assumptions!E76 -> 350 | E14: =Assumptions!F76 -> 360 | F14: =Assumptions!G76 -> 370 | G14: =Assumptions!H76 -> 380 | H14: =Assumptions!I76 -> 390
B15: Revenue | C15: =Assumptions!$C$44 -> 1156.9 | D15: =D13*D14 -> 2800 | E15: =E13*E14 -> 3600 | F15: =F13*F14 -> 5180 | G15: =G13*G14 -> 6840 | H15: =H13*H14 -> 8580
B17: DUV immersion (ArFi)
B18: Systems | C18: =Assumptions!$C$45 -> 131 | D18: =Assumptions!E81 -> 130 | E18: =Assumptions!F81 -> 145 | F18: =Assumptions!G81 -> 150 | G18: =Assumptions!H81 -> 145 | H18: =Assumptions!I81 -> 140
B19: ASP (EUR m) | C19: =C20/C18 -> 78.712977 | D19: =Assumptions!E86 -> 86 | E19: =Assumptions!F86 -> 87 | F19: =Assumptions!G86 -> 89 | G19: =Assumptions!H86 -> 91 | H19: =Assumptions!I86 -> 93
B20: Revenue | C20: =Assumptions!$C$46 -> 10311.4 | D20: =D18*D19 -> 11180 | E20: =E18*E19 -> 12615 | F20: =F18*F19 -> 13350 | G20: =G18*G19 -> 13195 | H20: =H18*H19 -> 13020
B22: Other segments
B23: Other DUV growth | D23: =Assumptions!E91 -> 0 | E23: =Assumptions!F91 -> 0 | F23: =Assumptions!G91 -> 0 | G23: =Assumptions!H91 -> 0 | H23: =Assumptions!I91 -> 0
B24: Other DUV revenue | C24: =Assumptions!$C$47 -> 1735.6 | D24: =C24*(1+D23) -> 1735.6 | E24: =D24*(1+E23) -> 1735.6 | F24: =E24*(1+F23) -> 1735.6 | G24: =F24*(1+G23) -> 1735.6 | H24: =G24*(1+H23) -> 1735.6
B25: Metrology & inspection growth | D25: =Assumptions!E96 -> 0.2 | E25: =Assumptions!F96 -> 0.1 | F25: =Assumptions!G96 -> 0.08 | G25: =Assumptions!H96 -> 0.06 | H25: =Assumptions!I96 -> 0.05
B26: Metrology & inspection revenue | C26: =Assumptions!$C$48 -> 824.6 | D26: =C26*(1+D25) -> 989.52 | E26: =D26*(1+E25) -> 1088.472 | F26: =E26*(1+F25) -> 1175.5498 | G26: =F26*(1+G25) -> 1246.0827 | H26: =G26*(1+H25) -> 1308.3869
B27: Installed base growth | D27: =Assumptions!E101 -> 0.3 | E27: =Assumptions!F101 -> 0.12 | F27: =Assumptions!G101 -> 0.1 | G27: =Assumptions!H101 -> 0.08 | H27: =Assumptions!I101 -> 0.07
B28: Installed base management revenue | C28: =Assumptions!$C$49 -> 8193 | D28: =C28*(1+D27) -> 10650.9 | E28: =D28*(1+E27) -> 11929.008 | F28: =E28*(1+F27) -> 13121.909 | G28: =F28*(1+G27) -> 14171.662 | H28: =G28*(1+H27) -> 15163.678
B30: Total
B31: Net system sales | C31: =C10+C15+C20+C24+C26 -> 24474.3 | D31: =D10+D15+D20+D24+D26 -> 33280.12 | E31: =E10+E15+E20+E24+E26 -> 38539.072 | F31: =F10+F15+F20+F24+F26 -> 43171.15 | G31: =G10+G15+G20+G24+G26 -> 46236.683 | H31: =H10+H15+H20+H24+H26 -> 48843.987
B32: Total net sales | C32: =C31+C28 -> 32667.3 | D32: =D31+D28 -> 43931.02 | E32: =E31+E28 -> 50468.08 | F32: =F31+F28 -> 56293.059 | G32: =G31+G28 -> 60408.344 | H32: =H31+H28 -> 64007.665 | J32: Feeds Forecast FY26E-FY30E revenue
B33: Growth % | C33: =C32/Historical!G6-1 -> 0.1558368 | D33: =D32/C32-1 -> 0.34480107 | E33: =E32/D32-1 -> 0.14880283 | F33: =F32/E32-1 -> 0.11541906 | G33: =G32/F32-1 -> 0.073104674 | H33: =H32/G32-1 -> 0.059583167
B34: EUV share of system sales | C34: =(C10+C15)/C31 -> 0.47407689 | D34: =(D10+D15)/D31 -> 0.58217939 | E34: =(E10+E15)/E31 -> 0.5993917 | F34: =(F10+F15)/F31 -> 0.62333295 | G34: =(G10+G15)/G31 -> 0.65013315 | H34: =(H10+H15)/H31 -> 0.67111639
B35: Installed base share of sales | C35: =C28/C32 -> 0.25080126 | D35: =D28/D32 -> 0.242446 | E35: =E28/E32 -> 0.23636738 | F35: =F28/F32 -> 0.23309994 | G35: =G28/G32 -> 0.23459775 | H35: =H28/H32 -> 0.23690409
B37: Capacity and guidance cross-checks
B38: Low-NA EUV capacity (stated, FY26-28) | D38: =Assumptions!$C$50 -> 65 | E38: =Assumptions!$C$50*(1+Assumptions!$C$52)^1 -> 84.5 | F38: =Assumptions!$C$50*(1+Assumptions!$C$52)^2 -> 109.85 | J38: FY26 stated; FY27 +30% planned; FY28 +30% under investigation [S4]
B39: Low-NA EUV utilisation | D39: =D8/D38 -> 1 | E39: =E8/E38 -> 0.88757396 | F39: =F8/F38 -> 0.74647246 | J39: Above 100% would need capacity ASML has not announced
B40: DUV immersion capacity (stated, FY26-28) | D40: =Assumptions!$C$51 -> 130 | E40: =Assumptions!$C$51*(1+Assumptions!$C$52)^1 -> 169 | F40: =Assumptions!$C$51*(1+Assumptions!$C$52)^2 -> 219.7
B41: DUV immersion utilisation | D41: =D18/D40 -> 1 | E41: =E18/E40 -> 0.85798817 | F41: =F18/F40 -> 0.6827492

Sheet Forecast
B1: Operating Forecast
B2: FY21A-FY25A linked from Historical (green); FY26E-FY30E from the revenue build and live drivers; FY31E-FY35E fade period. EUR millions.
B4: EUR m | C4: FY21A | D4: FY22A | E4: FY23A | F4: FY24A | G4: FY25A | H4: FY26E | I4: FY27E | J4: FY28E | K4: FY29E | L4: FY30E | M4: FY31E | N4: FY32E | O4: FY33E | P4: FY34E | Q4: FY35E | R4: Logic
B5: Scenario: | C5: =Assumptions!$C$9 -> Base | H5: Explicit forecast | M5: Fade period
B6: Fade step (years into fade) | M6: =COLUMN()-COLUMN($L$6) -> 1 | N6: =COLUMN()-COLUMN($L$6) -> 2 | O6: =COLUMN()-COLUMN($L$6) -> 3 | P6: =COLUMN()-COLUMN($L$6) -> 4 | Q6: =COLUMN()-COLUMN($L$6) -> 5
B8: Revenue | C8: =Historical!D6 -> 18611 | D8: =Historical!E6 -> 21173.4 | E8: =Historical!F6 -> 27558.5 | F8: =Historical!G6 -> 28262.9 | G8: =Historical!H6 -> 32667.3 | H8: ='Revenue Build'!D32 -> 43931.02 | I8: ='Revenue Build'!E32 -> 50468.08 | J8: ='Revenue Build'!F32 -> 56293.059 | K8: ='Revenue Build'!G32 -> 60408.344 | L8: ='Revenue Build'!H32 -> 64007.665 | M8: =L8*(1+M9) -> 67378.726 | N8: =M8*(1+N9) -> 70461.296 | O8: =N8*(1+O9) -> 73197.539 | P8: =O8*(1+P9) -> 75533.758 | Q8: =P8*(1+Q9) -> 77422.102 | R8: FY26-30: Revenue Build; FY31-35: prior x (1 + growth)
B9: Revenue growth % | C9: =Historical!D31 -> 0.3314018 | D9: =Historical!E31 -> 0.13768202 | E9: =Historical!F31 -> 0.30156234 | F9: =Historical!G31 -> 0.025560172 | G9: =Historical!H31 -> 0.1558368 | H9: =H8/G8-1 -> 0.34480107 | I9: =I8/H8-1 -> 0.14880283 | J9: =J8/I8-1 -> 0.11541906 | K9: =K8/J8-1 -> 0.073104674 | L9: =L8/K8-1 -> 0.059583167 | M9: =$L9+(Assumptions!$E$137-$L9)*M$6/Assumptions!$C$13 -> 0.052666533 | N9: =$L9+(Assumptions!$E$137-$L9)*N$6/Assumptions!$C$13 -> 0.0457499 | O9: =$L9+(Assumptions!$E$137-$L9)*O$6/Assumptions!$C$13 -> 0.038833267 | P9: =$L9+(Assumptions!$E$137-$L9)*P$6/Assumptions!$C$13 -> 0.031916633 | Q9: =$L9+(Assumptions!$E$137-$L9)*Q$6/Assumptions!$C$13 -> 0.025 | R9: Fade: FY30 growth + (g - FY30 growth) x step / fade years
B11: Gross profit | C11: =Historical!D8 -> 9809 | D11: =Historical!E8 -> 10700.1 | E11: =Historical!F8 -> 14136.1 | F11: =Historical!G8 -> 14492 | G11: =Historical!H8 -> 17258 | H11: =H8*H12 -> 24162.061 | I11: =I8*I12 -> 28262.125 | J11: =J8*J12 -> 31805.578 | K11: =K8*K12 -> 34432.756 | L11: =L8*L12 -> 36484.369 | M11: =M8*M12 -> 38405.874 | N11: =N8*N12 -> 40162.939 | O11: =O8*O12 -> 41722.597 | ... Q11: =Q8*Q12 -> 44130.598 | R11: Revenue x gross margin
B12: Gross margin % | C12: =Historical!D32 -> 0.52705389 | D12: =Historical!E32 -> 0.50535578 | E12: =Historical!F32 -> 0.51294882 | F12: =Historical!G32 -> 0.51275701 | G12: =Historical!H32 -> 0.52829588 | H12: =Assumptions!E107 -> 0.55 | I12: =Assumptions!F107 -> 0.56 | J12: =Assumptions!G107 -> 0.565 | K12: =Assumptions!H107 -> 0.57 | L12: =Assumptions!I107 -> 0.57 | M12: =$L12 -> 0.57 | N12: =$L12 -> 0.57 | O12: =$L12 -> 0.57 | P12: =$L12 -> 0.57 | Q12: =$L12 -> 0.57
B14: EBITDA | C14: =Historical!D33 -> 7221.1 | D14: =Historical!E33 -> 7084.3 | E14: =Historical!F33 -> 9782.1 | F14: =Historical!G33 -> 9941.2 | G14: =Historical!H33 -> 12327.3 | H14: =H8*H15 -> 18011.718 | I14: =I8*I15 -> 21196.594 | J14: =J8*J15 -> 23924.55 | K14: =K8*K15 -> 25975.588 | L14: =L8*L15 -> 27523.296 | M14: =M8*M15 -> 28972.852 | N14: =N8*N15 -> 30298.357 | O14: =O8*O15 -> 31474.942 | ... Q14: =Q8*Q15 -> 33291.504 | R14: Revenue x EBITDA margin
B15: EBITDA margin % | C15: =Historical!D34 -> 0.38800172 | D15: =Historical!E34 -> 0.3345849 | E15: =Historical!F34 -> 0.35495764 | F15: =Historical!G34 -> 0.35174027 | G15: =Historical!H34 -> 0.37735901 | H15: =Assumptions!E112 -> 0.41 | I15: =Assumptions!F112 -> 0.42 | J15: =Assumptions!G112 -> 0.425 | K15: =Assumptions!H112 -> 0.43 | L15: =Assumptions!I112 -> 0.43 | M15: =$L15 -> 0.43 | N15: =$L15 -> 0.43 | O15: =$L15 -> 0.43 | P15: =$L15 -> 0.43 | Q15: =$L15 -> 0.43 | R15: Fade years hold the FY30 ratio
B17: Depreciation & amortization | C17: =Historical!D12 -> 471 | D17: =Historical!E12 -> 583.6 | E17: =Historical!F12 -> 739.8 | F17: =Historical!G12 -> 918.6 | G17: =Historical!H12 -> 1025.9 | H17: =H8*H18 -> 1230.0686 | I17: =I8*I18 -> 1413.1062 | J17: =J8*J18 -> 1576.2056 | K17: =K8*K18 -> 1691.4336 | L17: =L8*L18 -> 1792.2146 | M17: =M8*M18 -> 1886.6043 | N17: =N8*N18 -> 1972.9163 | O17: =O8*O18 -> 2049.5311 | ... Q17: =Q8*Q18 -> 2167.8188 | R17: Revenue x D&A %
B18: D&A % revenue | C18: =Historical!D36 -> 0.025307614 | D18: =Historical!E36 -> 0.027562886 | E18: =Historical!F36 -> 0.026844712 | F18: =Historical!G36 -> 0.032501973 | G18: =Historical!H36 -> 0.031404493 | H18: =Assumptions!E117 -> 0.028 | I18: =Assumptions!F117 -> 0.028 | J18: =Assumptions!G117 -> 0.028 | K18: =Assumptions!H117 -> 0.028 | L18: =Assumptions!I117 -> 0.028 | M18: =$L18 -> 0.028 | N18: =$L18 -> 0.028 | O18: =$L18 -> 0.028 | P18: =$L18 -> 0.028 | Q18: =$L18 -> 0.028
B20: EBIT | C20: =Historical!D11 -> 6750.1 | D20: =Historical!E11 -> 6500.7 | E20: =Historical!F11 -> 9042.3 | F20: =Historical!G11 -> 9022.6 | G20: =Historical!H11 -> 11301.4 | H20: =H14-H17 -> 16781.65 | I20: =I14-I17 -> 19783.487 | J20: =J14-J17 -> 22348.344 | K20: =K14-K17 -> 24284.154 | L20: =L14-L17 -> 25731.081 | M20: =M14-M17 -> 27086.248 | N20: =N14-N17 -> 28325.441 | O20: =O14-O17 -> 29425.411 | ... Q20: =Q14-Q17 -> 31123.685 | R20: EBITDA - D&A
B21: EBIT margin % | C21: =Historical!D35 -> 0.36269411 | D21: =Historical!E35 -> 0.30702202 | E21: =Historical!F35 -> 0.32811292 | F21: =Historical!G35 -> 0.31923829 | G21: =Historical!H35 -> 0.34595452 | H21: =H20/H8 -> 0.382 | I21: =I20/I8 -> 0.392 | J21: =J20/J8 -> 0.397 | K21: =K20/K8 -> 0.402 | L21: =L20/L8 -> 0.402 | M21: =M20/M8 -> 0.402 | N21: =N20/N8 -> 0.402 | O21: =O20/O8 -> 0.402 | ... Q21: =Q20/Q8 -> 0.402
B23: Taxes on EBIT | C23: =Historical!D39 -> 1028.1936 | D23: =Historical!E39 -> 976.60026 | E23: =Historical!F39 -> 1429.2876 | F23: =Historical!G39 -> 1676.92 | G23: =Historical!H39 -> 1994.9184 | H23: =H20*H24 -> 2936.7887 | I23: =I20*I24 -> 3462.1103 | J23: =J20*J24 -> 3910.9602 | K23: =K20*K24 -> 4249.727 | L23: =L20*L24 -> 4502.9392 | M23: =M20*M24 -> 4740.0934 | N23: =N20*N24 -> 4956.9522 | O23: =O20*O24 -> 5149.4469 | ... Q23: =Q20*Q24 -> 5446.6449 | R23: EBIT x tax rate
B24: Tax rate | C24: =Historical!D38 -> 0.15232272 | D24: =Historical!E38 -> 0.15023002 | E24: =Historical!F38 -> 0.15806682 | F24: =Historical!G38 -> 0.18585774 | G24: =Historical!H38 -> 0.17651958 | H24: =Assumptions!E132 -> 0.175 | I24: =Assumptions!F132 -> 0.175 | J24: =Assumptions!G132 -> 0.175 | K24: =Assumptions!H132 -> 0.175 | L24: =Assumptions!I132 -> 0.175 | M24: =$L24 -> 0.175 | N24: =$L24 -> 0.175 | O24: =$L24 -> 0.175 | P24: =$L24 -> 0.175 | Q24: =$L24 -> 0.175
B25: NOPAT | C25: =Historical!D40 -> 5721.9064 | D25: =Historical!E40 -> 5524.0997 | E25: =Historical!F40 -> 7613.0124 | F25: =Historical!G40 -> 7345.68 | G25: =Historical!H40 -> 9306.4816 | H25: =H20-H23 -> 13844.861 | I25: =I20-I23 -> 16321.377 | J25: =J20-J23 -> 18437.384 | K25: =K20-K23 -> 20034.427 | L25: =L20-L23 -> 21228.142 | M25: =M20-M23 -> 22346.155 | N25: =N20-N23 -> 23368.489 | O25: =O20-O23 -> 24275.964 | ... Q25: =Q20-Q23 -> 25677.04 | R25: EBIT - taxes
B27: Capital expenditures | C27: =Historical!D41 -> 940.3 | D27: =Historical!E41 -> 1319.3 | E27: =Historical!F41 -> 2196.2 | F27: =Historical!G41 -> 2083.1 | G27: =Historical!H41 -> 1631.2 | H27: =H8*H28 -> 2416.2061 | I27: =I8*I28 -> 2775.7444 | J27: =J8*J28 -> 3096.1182 | K27: =K8*K28 -> 3322.4589 | L27: =L8*L28 -> 3520.4216 | M27: =M8*M28 -> 3705.83 | N27: =N8*N28 -> 3875.3713 | O27: =O8*O28 -> 4025.8646 | ... Q27: =Q8*Q28 -> 4258.2156 | R27: Revenue x CapEx %
B28: CapEx % revenue | C28: =Historical!D42 -> 0.050523884 | D28: =Historical!E42 -> 0.062309313 | E28: =Historical!F42 -> 0.079692291 | F28: =Historical!G42 -> 0.073704397 | G28: =Historical!H42 -> 0.049933726 | H28: =Assumptions!E122 -> 0.055 | I28: =Assumptions!F122 -> 0.055 | J28: =Assumptions!G122 -> 0.055 | K28: =Assumptions!H122 -> 0.055 | L28: =Assumptions!I122 -> 0.055 | M28: =$L28 -> 0.055 | N28: =$L28 -> 0.055 | O28: =$L28 -> 0.055 | P28: =$L28 -> 0.055 | Q28: =$L28 -> 0.055
B30: Net working capital | C30: =Historical!D43 -> -4414.7 | D30: =Historical!E43 -> -6818.4 | E30: =Historical!F43 -> -3716.3 | F30: =Historical!G43 -> -6670.4 | G30: =Historical!H43 -> -8920.2 | H30: =H8*H31 -> -5271.7224 | I30: =I8*I31 -> -6056.1696 | J30: =J8*J31 -> -6755.167 | K30: =K8*K31 -> -7249.0013 | L30: =L8*L31 -> -7680.9198 | M30: =M8*M31 -> -8085.4472 | N30: =N8*N31 -> -8455.3556 | O30: =O8*O31 -> -8783.7047 | ... Q30: =Q8*Q31 -> -9290.6522 | R30: Revenue x NWC %
B31: NWC % revenue | C31: =Historical!D44 -> -0.23720918 | D31: =Historical!E44 -> -0.32202669 | E31: =Historical!F44 -> -0.13485132 | F31: =Historical!G44 -> -0.23601258 | G31: =Historical!H44 -> -0.27306205 | H31: =Assumptions!E127 -> -0.12 | I31: =Assumptions!F127 -> -0.12 | J31: =Assumptions!G127 -> -0.12 | K31: =Assumptions!H127 -> -0.12 | L31: =Assumptions!I127 -> -0.12 | M31: =$L31 -> -0.12 | N31: =$L31 -> -0.12 | O31: =$L31 -> -0.12 | P31: =$L31 -> -0.12 | Q31: =$L31 -> -0.12
B32: Change in NWC (increase = outflow) | C32: =Historical!D45 -> -4765.1 | D32: =Historical!E45 -> -2403.7 | E32: =Historical!F45 -> 3102.1 | F32: =Historical!G45 -> -2954.1 | G32: =Historical!H45 -> -2249.8 | H32: =H30-G30 -> 3648.4776 | I32: =I30-H30 -> -784.4472 | J32: =J30-I30 -> -698.99743 | K32: =K30-J30 -> -493.83428 | L32: =L30-K30 -> -431.91845 | M32: =M30-L30 -> -404.52742 | N32: =N30-M30 -> -369.9084 | O32: =O30-N30 -> -328.34908 | ... Q32: =Q30-P30 -> -226.60127 | R32: NWC - prior NWC
B34: Unlevered free cash flow | C34: =Historical!D46 -> 10017.706 | D34: =Historical!E46 -> 7192.0997 | E34: =Historical!F46 -> 3054.5124 | F34: =Historical!G46 -> 9135.28 | G34: =Historical!H46 -> 10950.982 | H34: =H25+H17-H27-H32 -> 9010.2458 | I34: =I25+I17-I27-I32 -> 15743.186 | J34: =J25+J17-J27-J32 -> 17616.469 | K34: =K25+K17-K27-K32 -> 18897.236 | L34: =L25+L17-L27-L32 -> 19931.854 | M34: =M25+M17-M27-M32 -> 20931.456 | N34: =N25+N17-N27-N32 -> 21835.942 | O34: =O25+O17-O27-O32 -> 22627.979 | ... Q34: =Q25+Q17-Q27-Q32 -> 23813.245 | R34: NOPAT + D&A - CapEx - change in NWC
B35: UFCF margin % | C35: =Historical!D47 -> 0.53826804 | D35: =Historical!E47 -> 0.33967619 | E35: =Historical!F47 -> 0.1108374 | F35: =Historical!G47 -> 0.32322515 | G35: =Historical!H47 -> 0.33522763 | H35: =H34/H8 -> 0.20509985 | I35: =I34/I8 -> 0.31194343 | J35: =J34/J8 -> 0.31294212 | K35: =K34/K8 -> 0.31282493 | L35: =L34/L8 -> 0.31139792 | M35: =M34/M8 -> 0.31065379 | N35: =N34/N8 -> 0.30989981 | O35: =O34/O8 -> 0.30913579 | ... Q35: =Q34/Q8 -> 0.30757683
B37: Memo: implied opex % (GM - EBIT margin) | C37: =C12-C21 -> 0.16435979 | D37: =D12-D21 -> 0.19833376 | E37: =E12-E21 -> 0.18483589 | F37: =F12-F21 -> 0.19351871 | G37: =G12-G21 -> 0.18234136 | H37: =H12-H21 -> 0.168 | I37: =I12-I21 -> 0.168 | J37: =J12-J21 -> 0.168 | ... Q37: =Q12-Q21 -> 0.168 | R37: Sanity check: R&D + SG&A ~ 16-19% historically
B39: Revenue CAGR FY25A-FY30E | C39: =(L8/G8)^(1/5)-1 -> 0.143994
B40: Average EBITDA margin FY26-30 | C40: =AVERAGE(H15:L15) -> 0.423
B41: FY30E revenue vs 2030 company range (EUR 44-60bn) [S10] | C41: =IF(L8>60000,"Above range",IF(L8<44000,"Below range","Within range")) -> Above range

Sheet WACC
B1: Weighted Average Cost of Capital
B2: CAPM cost of equity, market-value weights. Inputs are linked from Assumptions (green).
B5: Cost of equity
B6: Risk-free rate | C6: =Assumptions!$C$32 -> 0.0351 | D6: 10Y German Bund: EUR, long-duration, matches EUR cash flows
B7: Regression beta vs STOXX Europe 600 (cross-check) | C7: =Assumptions!$C$34 -> 1.79 | D7: 60 monthly returns; R² 0.33, standard error ~0.34, so the 95% range is ~1.1-2.5
B8: Industry unlevered beta | C8: =Assumptions!$C$35 -> 1.39 | D8: Semiconductor equipment peers, cash-corrected (Damodaran)
B9: ASML market D/E | C9: =C27/C26 -> 0.0059618412 | D9: Debt / market capitalisation
B10: Relevered industry beta | C10: =C8*(1+(1-C20)*C9) -> 1.3961489 | D10: Hamada: Bu x (1 + (1 - t) x D/E)
B11: Weight on regression beta | C11: =Assumptions!$C$36 -> 0 | D11: 0% = pure bottom-up beta
B12: Selected beta | C12: =C11*C7+(1-C11)*C10 -> 1.3961489 | D12: Bottom-up beta: more stable than a single-stock regression
B13: Equity risk premium | C13: =Assumptions!$C$33 -> 0.0423 | D13: Implied mature-market ERP; Netherlands has no country premium
B14: Cost of equity (CAPM) | C14: =C6+C12*C13 -> 0.094157099 | D14: Rf + beta x ERP
B16: Cost of debt
B17: Risk-free rate | C17: =C6 -> 0.0351
B18: Credit spread (A1 / A+) | C18: =Assumptions!$C$37 -> 0.006 | D18: Spread for single-A EUR corporate bonds
B19: Pre-tax cost of debt | C19: =C17+C18 -> 0.0411 | D19: Rf + spread
B20: Tax rate (statutory) | C20: =Assumptions!$C$38 -> 0.258 | D20: Interest is deductible at the Dutch statutory rate
B21: After-tax cost of debt | C21: =C19*(1-C20) -> 0.0304962 | D21: Kd x (1 - t)
B23: Capital structure (market values)
B24: Share price (EUR) | C24: =Assumptions!$C$16 -> 1611.4
B25: Diluted shares (m) | C25: =Assumptions!$C$17 -> 384.9
B26: Market value of equity (E) | C26: =C24*C25 -> 620227.86 | D26: Price x diluted shares
B27: Debt (D) | C27: =Assumptions!$C$19 -> 3697.7 | D27: Book value as proxy for market value
B28: Total capital (D + E) | C28: =C26+C27 -> 623925.56
B29: Equity weight E / (D + E) | C29: =C26/C28 -> 0.99407349
B30: Debt weight D / (D + E) | C30: =C27/C28 -> 0.0059265083
B32: WACC
B33: WACC (CAPM) | C33: =C29*C14+C30*C21 -> 0.093779813 | D33: E/(D+E) x Ke + D/(D+E) x Kd x (1 - t)
B34: Scenario adjustment | C34: =Assumptions!$E$147 -> 0 | D34: 0 in Base; +/-0.5% in Bear/Bull
B35: WACC applied in DCF | C35: =C33+C34 -> 0.093779813

Sheet DCF
B1: Discounted Cash Flow
B2: Valuation at the valuation date on the 28-Jun-26 balance sheet. FY26 counts only H2 cash flow (stub); FY31-35 is the fade period; terminal value at end FY35.
B4: EUR m | E4: FY26E | F4: FY27E | G4: FY28E | H4: FY29E | I4: FY30E | J4: FY31E | K4: FY32E | L4: FY33E | M4: FY34E | N4: FY35E
B5: Period end | E5: =Assumptions!$C$7 -> 46387 | F5: =DATE(YEAR(E5)+1,12,31) -> 46752 | G5: =DATE(YEAR(F5)+1,12,31) -> 47118 | H5: =DATE(YEAR(G5)+1,12,31) -> 47483 | I5: =DATE(YEAR(H5)+1,12,31) -> 47848 | J5: =DATE(YEAR(I5)+1,12,31) -> 48213 | K5: =DATE(YEAR(J5)+1,12,31) -> 48579 | L5: =DATE(YEAR(K5)+1,12,31) -> 48944 | M5: =DATE(YEAR(L5)+1,12,31) -> 49309 | N5: =DATE(YEAR(M5)+1,12,31) -> 49674
B6: Years from valuation date to period end | E6: =(E5-Assumptions!$C$5)/365 -> 0.23287671 | F6: =E6+1 -> 1.2328767 | G6: =F6+1 -> 2.2328767 | H6: =G6+1 -> 3.2328767 | I6: =H6+1 -> 4.2328767 | J6: =I6+1 -> 5.2328767 | K6: =J6+1 -> 6.2328767 | L6: =K6+1 -> 7.2328767 | M6: =L6+1 -> 8.2328767 | N6: =M6+1 -> 9.2328767
B7: Discount period (mid-year if switched on) | E7: =IF(Assumptions!$C$11=1,E6/2,E6) -> 0.11643836 | F7: =IF(Assumptions!$C$11=1,F6-0.5,F6) -> 0.73287671 | G7: =IF(Assumptions!$C$11=1,G6-0.5,G6) -> 1.7328767 | H7: =IF(Assumptions!$C$11=1,H6-0.5,H6) -> 2.7328767 | I7: =IF(Assumptions!$C$11=1,I6-0.5,I6) -> 3.7328767 | J7: =IF(Assumptions!$C$11=1,J6-0.5,J6) -> 4.7328767 | K7: =IF(Assumptions!$C$11=1,K6-0.5,K6) -> 5.7328767 | L7: =IF(Assumptions!$C$11=1,L6-0.5,L6) -> 6.7328767 | M7: =IF(Assumptions!$C$11=1,M6-0.5,M6) -> 7.7328767 | N7: =IF(Assumptions!$C$11=1,N6-0.5,N6) -> 8.7328767 | O7: FY26 stub: mid-point of remaining period; later years: mid-year
B9: Unlevered free cash flow | E9: =Forecast!H34 -> 9010.2458 | F9: =Forecast!I34 -> 15743.186 | G9: =Forecast!J34 -> 17616.469 | H9: =Forecast!K34 -> 18897.236 | I9: =Forecast!L34 -> 19931.854 | J9: =Forecast!M34 -> 20931.456 | K9: =Forecast!N34 -> 21835.942 | L9: =Forecast!O34 -> 22627.979 | ... N9: =Forecast!Q34 -> 23813.245
B10: Less: H1-26 actual UFCF (already in 28-Jun cash) | E10: =-Assumptions!$C$21 -> 1290.9 | F10: 0 | G10: 0 | H10: 0 | I10: 0 | J10: 0 | K10: 0 | L10: 0 | M10: 0 | N10: 0 | O10: Avoids double counting: H1 cash flows are in the balance sheet already
B11: Cash flow to discount | E11: =E9+E10 -> 10301.146 | F11: =F9+F10 -> 15743.186 | G11: =G9+G10 -> 17616.469 | H11: =H9+H10 -> 18897.236 | I11: =I9+I10 -> 19931.854 | J11: =J9+J10 -> 20931.456 | K11: =K9+K10 -> 21835.942 | L11: =L9+L10 -> 22627.979 | ... N11: =N9+N10 -> 23813.245
B12: WACC | E12: =WACC!$C$35 -> 0.093779813 | F12: =WACC!$C$35 -> 0.093779813 | G12: =WACC!$C$35 -> 0.093779813 | H12: =WACC!$C$35 -> 0.093779813 | I12: =WACC!$C$35 -> 0.093779813 | J12: =WACC!$C$35 -> 0.093779813 | K12: =WACC!$C$35 -> 0.093779813 | L12: =WACC!$C$35 -> 0.093779813 | ... N12: =WACC!$C$35 -> 0.093779813
B13: Discount factor | E13: =1/(1+E12)^E7 -> 0.98961682 | F13: =1/(1+F12)^F7 -> 0.93641676 | G13: =1/(1+G12)^G7 -> 0.85612913 | H13: =1/(1+H12)^H7 -> 0.7827253 | I13: =1/(1+I12)^I7 -> 0.71561506 | J13: =1/(1+J12)^J7 -> 0.65425879 | K13: =1/(1+K12)^K7 -> 0.59816316 | L13: =1/(1+L12)^L7 -> 0.54687713 | ... N13: =1/(1+N12)^N7 -> 0.45711971
B14: PV of cash flow | E14: =E11*E13 -> 10194.187 | F14: =F11*F13 -> 14742.183 | G14: =G11*G13 -> 15081.972 | H14: =H11*H13 -> 14791.345 | I14: =I11*I13 -> 14263.534 | J14: =J11*J13 -> 13694.589 | K14: =K11*K13 -> 13061.456 | L14: =L11*L13 -> 12374.724 | ... N14: =N11*N13 -> 10885.504
B15: Sum of PV of cash flows FY26-FY35 | C15: =SUM(E14:N14) -> 130735.08
B16: of which explicit forecast FY26-FY30 | C16: =SUM(E14:I14) -> 69073.222
B17: of which fade period FY31-FY35 | C17: =SUM(J14:N14) -> 61661.854
B19: Valuation | C19: Gordon Growth | D19: Exit Multiple | E19: Blended
B20: Terminal-year UFCF (FY35E) | C20: =N9 -> 23813.245
B21: Terminal growth rate | C21: =Assumptions!$E$137 -> 0.025
B22: Terminal-year EBITDA (FY35E) | D22: =Forecast!Q14 -> 33291.504
B23: Exit EV/EBITDA multiple | D23: =Assumptions!$E$142 -> 20
B24: Terminal value at end FY35 | C24: =C20*(1+C21)/(WACC!$C$35-C21) -> 354879.94 | D24: =D22*D23 -> 665830.08 | F24: Gordon: FCF35 x (1 + g) / (WACC - g). Exit: EBITDA35 x multiple
B25: Discount period for terminal value | C25: =$N$6 -> 9.2328767 | D25: =$N$6 -> 9.2328767 | F25: Both terminal values discounted from end of FY35 (conservative)
B26: PV of terminal value | C26: =C24/(1+WACC!$C$35)^C25 -> 155112.38 | D26: =D24/(1+WACC!$C$35)^D25 -> 291023.73
B27: PV of FY26-FY35 cash flows | C27: =$C$15 -> 130735.08 | D27: =$C$15 -> 130735.08
B28: Enterprise value | C28: =C27+C26 -> 285847.45 | D28: =D27+D26 -> 421758.81 | E28: =Assumptions!$C$12*C28+(1-Assumptions!$C$12)*D28 -> 353803.13
B29: Terminal value % of EV | C29: =C26/C28 -> 0.5426404 | D29: =D26/D28 -> 0.69002408
B30: Plus: cash & short-term investments | C30: =Assumptions!$C$18 -> 7581.5 | D30: =Assumptions!$C$18 -> 7581.5
B31: Less: total debt | C31: =Assumptions!$C$19 -> 3697.7 | D31: =Assumptions!$C$19 -> 3697.7 | F31: Bonds + commercial paper; US GAAP operating leases excluded (lease cost already in EBITDA)
B32: Plus: non-operating investments | C32: =Assumptions!$C$20 -> 2310.7 | D32: =Assumptions!$C$20 -> 2310.7 | F32: Equity stakes (e.g. Mistral AI) and equity-method investments; their income is not in EBIT
B33: Equity value | C33: =C28+C30-C31+C32 -> 292041.95 | D33: =D28+D30-D31+D32 -> 427953.31 | E33: =Assumptions!$C$12*C33+(1-Assumptions!$C$12)*D33 -> 359997.63
B34: Diluted shares (m) | C34: =Assumptions!$C$17 -> 384.9 | D34: =Assumptions!$C$17 -> 384.9
B35: Implied share price (EUR) | C35: =C33/C34 -> 758.7476 | D35: =D33/D34 -> 1111.8558 | E35: =Assumptions!$C$12*C35+(1-Assumptions!$C$12)*D35 -> 935.30172
B36: Current share price (EUR) | C36: =Assumptions!$C$16 -> 1611.4 | D36: =Assumptions!$C$16 -> 1611.4 | E36: =Assumptions!$C$16 -> 1611.4
B37: Upside / (downside) | C37: =C35/C36-1 -> -0.52913764 | D37: =D35/D36-1 -> -0.31000631 | E37: =E35/E36-1 -> -0.41957198
B38: Cross-check: implied exit multiple / implied g | C38: =C24/D22 -> 10.659775 | D38: =(D24*WACC!$C$35-C20)/(D24+C20) -> 0.056011817 | F38: Gordon TV / EBITDA (x) | g implied by exit TV
B39: Reverse DCF: exit multiple implied by market price | D39: =((C36*C34-C30+C31-C32-C27)*(1+WACC!$C$35)^D25)/D22 -> 33.213668 | F39: Multiple needed in the Exit method to justify today's price
B40: Reverse DCF: perpetual growth implied by market price | C40: =(((C36*C34-C30+C31-C32-C27)*(1+WACC!$C$35)^C25)*WACC!$C$35-C20)/(((C36*C34-C30+C31-C32-C27)*(1+WACC!$C$35)^C25)+C20) -> 0.0707206 | F40: Perpetual growth needed in the Gordon method to justify today's price

Sheet Sensitivity
B1: Sensitivity Analysis
B2: Implied share price (EUR). Every cell is a live closed-form DCF; the grid centres on the live WACC, g and multiple. Base case boxed and shaded.
B4: Table 1: WACC vs terminal growth (Gordon Growth method) | M4: Grid steps
C5: WACC → | M5: WACC step | N5: 0.005
B6: g ↓ / WACC → | C6: =$G$6+(-4)*$N$5 -> 0.073779813 | D6: =$G$6+(-3)*$N$5 -> 0.078779813 | E6: =$G$6+(-2)*$N$5 -> 0.083779813 | F6: =$G$6+(-1)*$N$5 -> 0.088779813 | G6: =WACC!$C$35 -> 0.093779813 | H6: =$G$6+(1)*$N$5 -> 0.098779813 | I6: =$G$6+(2)*$N$5 -> 0.10377981 | J6: =$G$6+(3)*$N$5 -> 0.10877981 | K6: =$G$6+(4)*$N$5 -> 0.11377981 | M6: Terminal growth step | N6: 0.0025
B7: =$B$11+(-4)*$N$6 -> 0.015 | C7: =(SUMPRODUCT(DCF!$E$11:$N$11,1/(1+C$6)^DCF!$E$7:$N$7)+DCF!$N$9*(1+$B7)/(C$6-$B7)/(1+C$6)^DCF!$N$6+(DCF!$C$30-DCF!$C$31+DCF!$C$32))/DCF!$C$34 -> 936.80743 | D7: =(SUMPRODUCT(DCF!$E$11:$N$11,1/(1+D$6)^DCF!$E$7:$N$7)+DCF!$N$9*(1+$B7)/(D$6-$B7)/(1+D$6)^DCF!$N$6+(DCF!$C$30-DCF!$C$31+DCF!$C$32))/DCF!$C$34 -> 864.80327 | E7: =(SUMPRODUCT(DCF!$E$11:$N$11,1/(1+E$6)^DCF!$E$7:$N$7)+DCF!$N$9*(1+$B7)/(E$6-$B7)/(1+E$6)^DCF!$N$6+(DCF!$C$30-DCF!$C$31+DCF!$C$32))/DCF!$C$34 -> 803.37337 | F7: =(SUMPRODUCT(DCF!$E$11:$N$11,1/(1+F$6)^DCF!$E$7:$N$7)+DCF!$N$9*(1+$B7)/(F$6-$B7)/(1+F$6)^DCF!$N$6+(DCF!$C$30-DCF!$C$31+DCF!$C$32))/DCF!$C$34 -> 750.36185 | G7: =(SUMPRODUCT(DCF!$E$11:$N$11,1/(1+G$6)^DCF!$E$7:$N$7)+DCF!$N$9*(1+$B7)/(G$6-$B7)/(1+G$6)^DCF!$N$6+(DCF!$C$30-DCF!$C$31+DCF!$C$32))/DCF!$C$34 -> 704.16055 | H7: =(SUMPRODUCT(DCF!$E$11:$N$11,1/(1+H$6)^DCF!$E$7:$N$7)+DCF!$N$9*(1+$B7)/(H$6-$B7)/(1+H$6)^DCF!$N$6+(DCF!$C$30-DCF!$C$31+DCF!$C$32))/DCF!$C$34 -> 663.54553 | I7: =(SUMPRODUCT(DCF!$E$11:$N$11,1/(1+I$6)^DCF!$E$7:$N$7)+DCF!$N$9*(1+$B7)/(I$6-$B7)/(1+I$6)^DCF!$N$6+(DCF!$C$30-DCF!$C$31+DCF!$C$32))/DCF!$C$34 -> 627.56884 | J7: =(SUMPRODUCT(DCF!$E$11:$N$11,1/(1+J$6)^DCF!$E$7:$N$7)+DCF!$N$9*(1+$B7)/(J$6-$B7)/(1+J$6)^DCF!$N$6+(DCF!$C$30-DCF!$C$31+DCF!$C$32))/DCF!$C$34 -> 595.48497 | K7: =(SUMPRODUCT(DCF!$E$11:$N$11,1/(1+K$6)^DCF!$E$7:$N$7)+DCF!$N$9*(1+$B7)/(K$6-$B7)/(1+K$6)^DCF!$N$6+(DCF!$C$30-DCF!$C$31+DCF!$C$32))/DCF!$C$34 -> 566.69956 | M7: Exit multiple step | N7: 2
B8: =$B$11+(-3)*$N$6 -> 0.0175 | C8: =(SUMPRODUCT(DCF!$E$11:$N$11,1/(1+C$6)^DCF!$E$7:$N$7)+DCF!$N$9*(1+$B8)/(C$6-$B8)/(1+C$6)^DCF!$N$6+(DCF!$C$30-DCF!$C$31+DCF!$C$32))/DCF!$C$34 -> 962.8275 | D8: =(SUMPRODUCT(DCF!$E$11:$N$11,1/(1+D$6)^DCF!$E$7:$N$7)+DCF!$N$9*(1+$B8)/(D$6-$B8)/(1+D$6)^DCF!$N$6+(DCF!$C$30-DCF!$C$31+DCF!$C$32))/DCF!$C$34 -> 886.00046 | E8: =(SUMPRODUCT(DCF!$E$11:$N$11,1/(1+E$6)^DCF!$E$7:$N$7)+DCF!$N$9*(1+$B8)/(E$6-$B8)/(1+E$6)^DCF!$N$6+(DCF!$C$30-DCF!$C$31+DCF!$C$32))/DCF!$C$34 -> 820.86792 | F8: =(SUMPRODUCT(DCF!$E$11:$N$11,1/(1+F$6)^DCF!$E$7:$N$7)+DCF!$N$9*(1+$B8)/(F$6-$B8)/(1+F$6)^DCF!$N$6+(DCF!$C$30-DCF!$C$31+DCF!$C$32))/DCF!$C$34 -> 764.96288 | G8: =(SUMPRODUCT(DCF!$E$11:$N$11,1/(1+G$6)^DCF!$E$7:$N$7)+DCF!$N$9*(1+$B8)/(G$6-$B8)/(1+G$6)^DCF!$N$6+(DCF!$C$30-DCF!$C$31+DCF!$C$32))/DCF!$C$34 -> 716.46553 | H8: =(SUMPRODUCT(DCF!$E$11:$N$11,1/(1+H$6)^DCF!$E$7:$N$7)+DCF!$N$9*(1+$B8)/(H$6-$B8)/(1+H$6)^DCF!$N$6+(DCF!$C$30-DCF!$C$31+DCF!$C$32))/DCF!$C$34 -> 674.00419 | I8: =(SUMPRODUCT(DCF!$E$11:$N$11,1/(1+I$6)^DCF!$E$7:$N$7)+DCF!$N$9*(1+$B8)/(I$6-$B8)/(1+I$6)^DCF!$N$6+(DCF!$C$30-DCF!$C$31+DCF!$C$32))/DCF!$C$34 -> 636.52541 | J8: =(SUMPRODUCT(DCF!$E$11:$N$11,1/(1+J$6)^DCF!$E$7:$N$7)+DCF!$N$9*(1+$B8)/(J$6-$B8)/(1+J$6)^DCF!$N$6+(DCF!$C$30-DCF!$C$31+DCF!$C$32))/DCF!$C$34 -> 603.20681 | K8: =(SUMPRODUCT(DCF!$E$11:$N$11,1/(1+K$6)^DCF!$E$7:$N$7)+DCF!$N$9*(1+$B8)/(K$6-$B8)/(1+K$6)^DCF!$N$6+(DCF!$C$30-DCF!$C$31+DCF!$C$32))/DCF!$C$34 -> 573.39708
B9: =$B$11+(-2)*$N$6 -> 0.02 | C9: =(SUMPRODUCT(DCF!$E$11:$N$11,1/(1+C$6)^DCF!$E$7:$N$7)+DCF!$N$9*(1+$B9)/(C$6-$B9)/(1+C$6)^DCF!$N$6+(DCF!$C$30-DCF!$C$31+DCF!$C$32))/DCF!$C$34 -> 991.2667 | D9: =(SUMPRODUCT(DCF!$E$11:$N$11,1/(1+D$6)^DCF!$E$7:$N$7)+DCF!$N$9*(1+$B9)/(D$6-$B9)/(1+D$6)^DCF!$N$6+(DCF!$C$30-DCF!$C$31+DCF!$C$32))/DCF!$C$34 -> 909.00075 | E9: =(SUMPRODUCT(DCF!$E$11:$N$11,1/(1+E$6)^DCF!$E$7:$N$7)+DCF!$N$9*(1+$B9)/(E$6-$B9)/(1+E$6)^DCF!$N$6+(DCF!$C$30-DCF!$C$31+DCF!$C$32))/DCF!$C$34 -> 839.73396 | F9: =(SUMPRODUCT(DCF!$E$11:$N$11,1/(1+F$6)^DCF!$E$7:$N$7)+DCF!$N$9*(1+$B9)/(F$6-$B9)/(1+F$6)^DCF!$N$6+(DCF!$C$30-DCF!$C$31+DCF!$C$32))/DCF!$C$34 -> 780.62535 | G9: =(SUMPRODUCT(DCF!$E$11:$N$11,1/(1+G$6)^DCF!$E$7:$N$7)+DCF!$N$9*(1+$B9)/(G$6-$B9)/(1+G$6)^DCF!$N$6+(DCF!$C$30-DCF!$C$31+DCF!$C$32))/DCF!$C$34 -> 729.60442 | H9: =(SUMPRODUCT(DCF!$E$11:$N$11,1/(1+H$6)^DCF!$E$7:$N$7)+DCF!$N$9*(1+$B9)/(H$6-$B9)/(1+H$6)^DCF!$N$6+(DCF!$C$30-DCF!$C$31+DCF!$C$32))/DCF!$C$34 -> 685.12664 | I9: =(SUMPRODUCT(DCF!$E$11:$N$11,1/(1+I$6)^DCF!$E$7:$N$7)+DCF!$N$9*(1+$B9)/(I$6-$B9)/(1+I$6)^DCF!$N$6+(DCF!$C$30-DCF!$C$31+DCF!$C$32))/DCF!$C$34 -> 646.0165 | J9: =(SUMPRODUCT(DCF!$E$11:$N$11,1/(1+J$6)^DCF!$E$7:$N$7)+DCF!$N$9*(1+$B9)/(J$6-$B9)/(1+J$6)^DCF!$N$6+(DCF!$C$30-DCF!$C$31+DCF!$C$32))/DCF!$C$34 -> 611.36353 | K9: =(SUMPRODUCT(DCF!$E$11:$N$11,1/(1+K$6)^DCF!$E$7:$N$7)+DCF!$N$9*(1+$B9)/(K$6-$B9)/(1+K$6)^DCF!$N$6+(DCF!$C$30-DCF!$C$31+DCF!$C$32))/DCF!$C$34 -> 580.45168
B10: =$B$11+(-1)*$N$6 -> 0.0225 | C10: =(SUMPRODUCT(DCF!$E$11:$N$11,1/(1+C$6)^DCF!$E$7:$N$7)+DCF!$N$9*(1+$B10)/(C$6-$B10)/(1+C$6)^DCF!$N$6+(DCF!$C$30-DCF!$C$31+DCF!$C$32))/DCF!$C$34 -> 1022.4788 | D10: =(SUMPRODUCT(DCF!$E$11:$N$11,1/(1+D$6)^DCF!$E$7:$N$7)+DCF!$N$9*(1+$B10)/(D$6-$B10)/(1+D$6)^DCF!$N$6+(DCF!$C$30-DCF!$C$31+DCF!$C$32))/DCF!$C$34 -> 934.04442 | E10: =(SUMPRODUCT(DCF!$E$11:$N$11,1/(1+E$6)^DCF!$E$7:$N$7)+DCF!$N$9*(1+$B10)/(E$6-$B10)/(1+E$6)^DCF!$N$6+(DCF!$C$30-DCF!$C$31+DCF!$C$32))/DCF!$C$34 -> 860.13934 | F10: =(SUMPRODUCT(DCF!$E$11:$N$11,1/(1+F$6)^DCF!$E$7:$N$7)+DCF!$N$9*(1+$B10)/(F$6-$B10)/(1+F$6)^DCF!$N$6+(DCF!$C$30-DCF!$C$31+DCF!$C$32))/DCF!$C$34 -> 797.46936 | G10: =(SUMPRODUCT(DCF!$E$11:$N$11,1/(1+G$6)^DCF!$E$7:$N$7)+DCF!$N$9*(1+$B10)/(G$6-$B10)/(1+G$6)^DCF!$N$6+(DCF!$C$30-DCF!$C$31+DCF!$C$32))/DCF!$C$34 -> 743.66494 | H10: =(SUMPRODUCT(DCF!$E$11:$N$11,1/(1+H$6)^DCF!$E$7:$N$7)+DCF!$N$9*(1+$B10)/(H$6-$B10)/(1+H$6)^DCF!$N$6+(DCF!$C$30-DCF!$C$31+DCF!$C$32))/DCF!$C$34 -> 696.97815 | I10: =(SUMPRODUCT(DCF!$E$11:$N$11,1/(1+I$6)^DCF!$E$7:$N$7)+DCF!$N$9*(1+$B10)/(I$6-$B10)/(1+I$6)^DCF!$N$6+(DCF!$C$30-DCF!$C$31+DCF!$C$32))/DCF!$C$34 -> 656.09144 | J10: =(SUMPRODUCT(DCF!$E$11:$N$11,1/(1+J$6)^DCF!$E$7:$N$7)+DCF!$N$9*(1+$B10)/(J$6-$B10)/(1+J$6)^DCF!$N$6+(DCF!$C$30-DCF!$C$31+DCF!$C$32))/DCF!$C$34 -> 619.99295 | K10: =(SUMPRODUCT(DCF!$E$11:$N$11,1/(1+K$6)^DCF!$E$7:$N$7)+DCF!$N$9*(1+$B10)/(K$6-$B10)/(1+K$6)^DCF!$N$6+(DCF!$C$30-DCF!$C$31+DCF!$C$32))/DCF!$C$34 -> 587.89272
B11: =Assumptions!$E$137 -> 0.025 | C11: =(SUMPRODUCT(DCF!$E$11:$N$11,1/(1+C$6)^DCF!$E$7:$N$7)+DCF!$N$9*(1+$B11)/(C$6-$B11)/(1+C$6)^DCF!$N$6+(DCF!$C$30-DCF!$C$31+DCF!$C$32))/DCF!$C$34 -> 1056.8903 | D11: =(SUMPRODUCT(DCF!$E$11:$N$11,1/(1+D$6)^DCF!$E$7:$N$7)+DCF!$N$9*(1+$B11)/(D$6-$B11)/(1+D$6)^DCF!$N$6+(DCF!$C$30-DCF!$C$31+DCF!$C$32))/DCF!$C$34 -> 961.41645 | E11: =(SUMPRODUCT(DCF!$E$11:$N$11,1/(1+E$6)^DCF!$E$7:$N$7)+DCF!$N$9*(1+$B11)/(E$6-$B11)/(1+E$6)^DCF!$N$6+(DCF!$C$30-DCF!$C$31+DCF!$C$32))/DCF!$C$34 -> 882.28046 | F11: =(SUMPRODUCT(DCF!$E$11:$N$11,1/(1+F$6)^DCF!$E$7:$N$7)+DCF!$N$9*(1+$B11)/(F$6-$B11)/(1+F$6)^DCF!$N$6+(DCF!$C$30-DCF!$C$31+DCF!$C$32))/DCF!$C$34 -> 815.63385 | G11: =(SUMPRODUCT(DCF!$E$11:$N$11,1/(1+G$6)^DCF!$E$7:$N$7)+DCF!$N$9*(1+$B11)/(G$6-$B11)/(1+G$6)^DCF!$N$6+(DCF!$C$30-DCF!$C$31+DCF!$C$32))/DCF!$C$34 -> 758.7476 | H11: =(SUMPRODUCT(DCF!$E$11:$N$11,1/(1+H$6)^DCF!$E$7:$N$7)+DCF!$N$9*(1+$B11)/(H$6-$B11)/(1+H$6)^DCF!$N$6+(DCF!$C$30-DCF!$C$31+DCF!$C$32))/DCF!$C$34 -> 709.63282 | I11: =(SUMPRODUCT(DCF!$E$11:$N$11,1/(1+I$6)^DCF!$E$7:$N$7)+DCF!$N$9*(1+$B11)/(I$6-$B11)/(1+I$6)^DCF!$N$6+(DCF!$C$30-DCF!$C$31+DCF!$C$32))/DCF!$C$34 -> 666.80583 | J11: =(SUMPRODUCT(DCF!$E$11:$N$11,1/(1+J$6)^DCF!$E$7:$N$7)+DCF!$N$9*(1+$B11)/(J$6-$B11)/(1+J$6)^DCF!$N$6+(DCF!$C$30-DCF!$C$31+DCF!$C$32))/DCF!$C$34 -> 629.13737 | K11: =(SUMPRODUCT(DCF!$E$11:$N$11,1/(1+K$6)^DCF!$E$7:$N$7)+DCF!$N$9*(1+$B11)/(K$6-$B11)/(1+K$6)^DCF!$N$6+(DCF!$C$30-DCF!$C$31+DCF!$C$32))/DCF!$C$34 -> 595.75283
B12: =$B$11+(1)*$N$6 -> 0.0275 | C12: =(SUMPRODUCT(DCF!$E$11:$N$11,1/(1+C$6)^DCF!$E$7:$N$7)+DCF!$N$9*(1+$B12)/(C$6-$B12)/(1+C$6)^DCF!$N$6+(DCF!$C$30-DCF!$C$31+DCF!$C$32))/DCF!$C$34 -> 1095.0195 | D12: =(SUMPRODUCT(DCF!$E$11:$N$11,1/(1+D$6)^DCF!$E$7:$N$7)+DCF!$N$9*(1+$B12)/(D$6-$B12)/(1+D$6)^DCF!$N$6+(DCF!$C$30-DCF!$C$31+DCF!$C$32))/DCF!$C$34 -> 991.45737 | E12: =(SUMPRODUCT(DCF!$E$11:$N$11,1/(1+E$6)^DCF!$E$7:$N$7)+DCF!$N$9*(1+$B12)/(E$6-$B12)/(1+E$6)^DCF!$N$6+(DCF!$C$30-DCF!$C$31+DCF!$C$32))/DCF!$C$34 -> 906.38864 | F12: =(SUMPRODUCT(DCF!$E$11:$N$11,1/(1+F$6)^DCF!$E$7:$N$7)+DCF!$N$9*(1+$B12)/(F$6-$B12)/(1+F$6)^DCF!$N$6+(DCF!$C$30-DCF!$C$31+DCF!$C$32))/DCF!$C$34 -> 835.28043 | G12: =(SUMPRODUCT(DCF!$E$11:$N$11,1/(1+G$6)^DCF!$E$7:$N$7)+DCF!$N$9*(1+$B12)/(G$6-$B12)/(1+G$6)^DCF!$N$6+(DCF!$C$30-DCF!$C$31+DCF!$C$32))/DCF!$C$34 -> 774.96807 | H12: =(SUMPRODUCT(DCF!$E$11:$N$11,1/(1+H$6)^DCF!$E$7:$N$7)+DCF!$N$9*(1+$B12)/(H$6-$B12)/(1+H$6)^DCF!$N$6+(DCF!$C$30-DCF!$C$31+DCF!$C$32))/DCF!$C$34 -> 723.17517 | I12: =(SUMPRODUCT(DCF!$E$11:$N$11,1/(1+I$6)^DCF!$E$7:$N$7)+DCF!$N$9*(1+$B12)/(I$6-$B12)/(1+I$6)^DCF!$N$6+(DCF!$C$30-DCF!$C$31+DCF!$C$32))/DCF!$C$34 -> 678.22252 | J12: =(SUMPRODUCT(DCF!$E$11:$N$11,1/(1+J$6)^DCF!$E$7:$N$7)+DCF!$N$9*(1+$B12)/(J$6-$B12)/(1+J$6)^DCF!$N$6+(DCF!$C$30-DCF!$C$31+DCF!$C$32))/DCF!$C$34 -> 638.84432 | K12: =(SUMPRODUCT(DCF!$E$11:$N$11,1/(1+K$6)^DCF!$E$7:$N$7)+DCF!$N$9*(1+$B12)/(K$6-$B12)/(1+K$6)^DCF!$N$6+(DCF!$C$30-DCF!$C$31+DCF!$C$32))/DCF!$C$34 -> 604.06844
B13: =$B$11+(2)*$N$6 -> 0.03 | C13: =(SUMPRODUCT(DCF!$E$11:$N$11,1/(1+C$6)^DCF!$E$7:$N$7)+DCF!$N$9*(1+$B13)/(C$6-$B13)/(1+C$6)^DCF!$N$6+(DCF!$C$30-DCF!$C$31+DCF!$C$32))/DCF!$C$34 -> 1137.5033 | D13: =(SUMPRODUCT(DCF!$E$11:$N$11,1/(1+D$6)^DCF!$E$7:$N$7)+DCF!$N$9*(1+$B13)/(D$6-$B13)/(1+D$6)^DCF!$N$6+(DCF!$C$30-DCF!$C$31+DCF!$C$32))/DCF!$C$34 -> 1024.5775 | E13: =(SUMPRODUCT(DCF!$E$11:$N$11,1/(1+E$6)^DCF!$E$7:$N$7)+DCF!$N$9*(1+$B13)/(E$6-$B13)/(1+E$6)^DCF!$N$6+(DCF!$C$30-DCF!$C$31+DCF!$C$32))/DCF!$C$34 -> 932.7382 | F13: =(SUMPRODUCT(DCF!$E$11:$N$11,1/(1+F$6)^DCF!$E$7:$N$7)+DCF!$N$9*(1+$B13)/(F$6-$B13)/(1+F$6)^DCF!$N$6+(DCF!$C$30-DCF!$C$31+DCF!$C$32))/DCF!$C$34 -> 856.59822 | G13: =(SUMPRODUCT(DCF!$E$11:$N$11,1/(1+G$6)^DCF!$E$7:$N$7)+DCF!$N$9*(1+$B13)/(G$6-$B13)/(1+G$6)^DCF!$N$6+(DCF!$C$30-DCF!$C$31+DCF!$C$32))/DCF!$C$34 -> 792.46013 | H13: =(SUMPRODUCT(DCF!$E$11:$N$11,1/(1+H$6)^DCF!$E$7:$N$7)+DCF!$N$9*(1+$B13)/(H$6-$B13)/(1+H$6)^DCF!$N$6+(DCF!$C$30-DCF!$C$31+DCF!$C$32))/DCF!$C$34 -> 737.702 | I13: =(SUMPRODUCT(DCF!$E$11:$N$11,1/(1+I$6)^DCF!$E$7:$N$7)+DCF!$N$9*(1+$B13)/(I$6-$B13)/(1+I$6)^DCF!$N$6+(DCF!$C$30-DCF!$C$31+DCF!$C$32))/DCF!$C$34 -> 690.41291 | J13: =(SUMPRODUCT(DCF!$E$11:$N$11,1/(1+J$6)^DCF!$E$7:$N$7)+DCF!$N$9*(1+$B13)/(J$6-$B13)/(1+J$6)^DCF!$N$6+(DCF!$C$30-DCF!$C$31+DCF!$C$32))/DCF!$C$34 -> 649.16735 | K13: =(SUMPRODUCT(DCF!$E$11:$N$11,1/(1+K$6)^DCF!$E$7:$N$7)+DCF!$N$9*(1+$B13)/(K$6-$B13)/(1+K$6)^DCF!$N$6+(DCF!$C$30-DCF!$C$31+DCF!$C$32))/DCF!$C$34 -> 612.88032
B14: =$B$11+(3)*$N$6 -> 0.0325 | C14: =(SUMPRODUCT(DCF!$E$11:$N$11,1/(1+C$6)^DCF!$E$7:$N$7)+DCF!$N$9*(1+$B14)/(C$6-$B14)/(1+C$6)^DCF!$N$6+(DCF!$C$30-DCF!$C$31+DCF!$C$32))/DCF!$C$34 -> 1185.133 | D14: =(SUMPRODUCT(DCF!$E$11:$N$11,1/(1+D$6)^DCF!$E$7:$N$7)+DCF!$N$9*(1+$B14)/(D$6-$B14)/(1+D$6)^DCF!$N$6+(DCF!$C$30-DCF!$C$31+DCF!$C$32))/DCF!$C$34 -> 1061.2759 | E14: =(SUMPRODUCT(DCF!$E$11:$N$11,1/(1+E$6)^DCF!$E$7:$N$7)+DCF!$N$9*(1+$B14)/(E$6-$B14)/(1+E$6)^DCF!$N$6+(DCF!$C$30-DCF!$C$31+DCF!$C$32))/DCF!$C$34 -> 961.65695 | F14: =(SUMPRODUCT(DCF!$E$11:$N$11,1/(1+F$6)^DCF!$E$7:$N$7)+DCF!$N$9*(1+$B14)/(F$6-$B14)/(1+F$6)^DCF!$N$6+(DCF!$C$30-DCF!$C$31+DCF!$C$32))/DCF!$C$34 -> 879.80991 | G14: =(SUMPRODUCT(DCF!$E$11:$N$11,1/(1+G$6)^DCF!$E$7:$N$7)+DCF!$N$9*(1+$B14)/(G$6-$B14)/(1+G$6)^DCF!$N$6+(DCF!$C$30-DCF!$C$31+DCF!$C$32))/DCF!$C$34 -> 811.37943 | H14: =(SUMPRODUCT(DCF!$E$11:$N$11,1/(1+H$6)^DCF!$E$7:$N$7)+DCF!$N$9*(1+$B14)/(H$6-$B14)/(1+H$6)^DCF!$N$6+(DCF!$C$30-DCF!$C$31+DCF!$C$32))/DCF!$C$34 -> 753.32469 | I14: =(SUMPRODUCT(DCF!$E$11:$N$11,1/(1+I$6)^DCF!$E$7:$N$7)+DCF!$N$9*(1+$B14)/(I$6-$B14)/(1+I$6)^DCF!$N$6+(DCF!$C$30-DCF!$C$31+DCF!$C$32))/DCF!$C$34 -> 703.4584 | J14: =(SUMPRODUCT(DCF!$E$11:$N$11,1/(1+J$6)^DCF!$E$7:$N$7)+DCF!$N$9*(1+$B14)/(J$6-$B14)/(1+J$6)^DCF!$N$6+(DCF!$C$30-DCF!$C$31+DCF!$C$32))/DCF!$C$34 -> 660.16703 | K14: =(SUMPRODUCT(DCF!$E$11:$N$11,1/(1+K$6)^DCF!$E$7:$N$7)+DCF!$N$9*(1+$B14)/(K$6-$B14)/(1+K$6)^DCF!$N$6+(DCF!$C$30-DCF!$C$31+DCF!$C$32))/DCF!$C$34 -> 622.23428
B15: =$B$11+(4)*$N$6 -> 0.035 | C15: =(SUMPRODUCT(DCF!$E$11:$N$11,1/(1+C$6)^DCF!$E$7:$N$7)+DCF!$N$9*(1+$B15)/(C$6-$B15)/(1+C$6)^DCF!$N$6+(DCF!$C$30-DCF!$C$31+DCF!$C$32))/DCF!$C$34 -> 1238.9037 | D15: =(SUMPRODUCT(DCF!$E$11:$N$11,1/(1+D$6)^DCF!$E$7:$N$7)+DCF!$N$9*(1+$B15)/(D$6-$B15)/(1+D$6)^DCF!$N$6+(DCF!$C$30-DCF!$C$31+DCF!$C$32))/DCF!$C$34 -> 1102.1656 | E15: =(SUMPRODUCT(DCF!$E$11:$N$11,1/(1+E$6)^DCF!$E$7:$N$7)+DCF!$N$9*(1+$B15)/(E$6-$B15)/(1+E$6)^DCF!$N$6+(DCF!$C$30-DCF!$C$31+DCF!$C$32))/DCF!$C$34 -> 993.53991 | F15: =(SUMPRODUCT(DCF!$E$11:$N$11,1/(1+F$6)^DCF!$E$7:$N$7)+DCF!$N$9*(1+$B15)/(F$6-$B15)/(1+F$6)^DCF!$N$6+(DCF!$C$30-DCF!$C$31+DCF!$C$32))/DCF!$C$34 -> 905.17964 | G15: =(SUMPRODUCT(DCF!$E$11:$N$11,1/(1+G$6)^DCF!$E$7:$N$7)+DCF!$N$9*(1+$B15)/(G$6-$B15)/(1+G$6)^DCF!$N$6+(DCF!$C$30-DCF!$C$31+DCF!$C$32))/DCF!$C$34 -> 831.90805 | H15: =(SUMPRODUCT(DCF!$E$11:$N$11,1/(1+H$6)^DCF!$E$7:$N$7)+DCF!$N$9*(1+$B15)/(H$6-$B15)/(1+H$6)^DCF!$N$6+(DCF!$C$30-DCF!$C$31+DCF!$C$32))/DCF!$C$34 -> 770.17212 | I15: =(SUMPRODUCT(DCF!$E$11:$N$11,1/(1+I$6)^DCF!$E$7:$N$7)+DCF!$N$9*(1+$B15)/(I$6-$B15)/(1+I$6)^DCF!$N$6+(DCF!$C$30-DCF!$C$31+DCF!$C$32))/DCF!$C$34 -> 717.45226 | J15: =(SUMPRODUCT(DCF!$E$11:$N$11,1/(1+J$6)^DCF!$E$7:$N$7)+DCF!$N$9*(1+$B15)/(J$6-$B15)/(1+J$6)^DCF!$N$6+(DCF!$C$30-DCF!$C$31+DCF!$C$32))/DCF!$C$34 -> 671.91215 | K15: =(SUMPRODUCT(DCF!$E$11:$N$11,1/(1+K$6)^DCF!$E$7:$N$7)+DCF!$N$9*(1+$B15)/(K$6-$B15)/(1+K$6)^DCF!$N$6+(DCF!$C$30-DCF!$C$31+DCF!$C$32))/DCF!$C$34 -> 632.18191
B17: Table 2: WACC vs exit EV/EBITDA multiple (Exit Multiple method)
C18: WACC →
B19: Multiple ↓ / WACC → | C19: =$G$19+(-4)*$N$5 -> 0.073779813 | D19: =$G$19+(-3)*$N$5 -> 0.078779813 | E19: =$G$19+(-2)*$N$5 -> 0.083779813 | F19: =$G$19+(-1)*$N$5 -> 0.088779813 | G19: =WACC!$C$35 -> 0.093779813 | H19: =$G$19+(1)*$N$5 -> 0.098779813 | I19: =$G$19+(2)*$N$5 -> 0.10377981 | J19: =$G$19+(3)*$N$5 -> 0.10877981 | K19: =$G$19+(4)*$N$5 -> 0.11377981
B20: =$B$24+(-4)*$N$7 -> 12 | C20: =(SUMPRODUCT(DCF!$E$11:$N$11,1/(1+C$19)^DCF!$E$7:$N$7)+Forecast!$Q$14*$B20/(1+C$19)^DCF!$N$6+(DCF!$C$30-DCF!$C$31+DCF!$C$32))/DCF!$C$34 -> 921.04619 | D20: =(SUMPRODUCT(DCF!$E$11:$N$11,1/(1+D$19)^DCF!$E$7:$N$7)+Forecast!$Q$14*$B20/(1+D$19)^DCF!$N$6+(DCF!$C$30-DCF!$C$31+DCF!$C$32))/DCF!$C$34 -> 891.28821 | E20: =(SUMPRODUCT(DCF!$E$11:$N$11,1/(1+E$19)^DCF!$E$7:$N$7)+Forecast!$Q$14*$B20/(1+E$19)^DCF!$N$6+(DCF!$C$30-DCF!$C$31+DCF!$C$32))/DCF!$C$34 -> 862.80439 | F20: =(SUMPRODUCT(DCF!$E$11:$N$11,1/(1+F$19)^DCF!$E$7:$N$7)+Forecast!$Q$14*$B20/(1+F$19)^DCF!$N$6+(DCF!$C$30-DCF!$C$31+DCF!$C$32))/DCF!$C$34 -> 835.53284 | G20: =(SUMPRODUCT(DCF!$E$11:$N$11,1/(1+G$19)^DCF!$E$7:$N$7)+Forecast!$Q$14*$B20/(1+G$19)^DCF!$N$6+(DCF!$C$30-DCF!$C$31+DCF!$C$32))/DCF!$C$34 -> 809.41496 | H20: =(SUMPRODUCT(DCF!$E$11:$N$11,1/(1+H$19)^DCF!$E$7:$N$7)+Forecast!$Q$14*$B20/(1+H$19)^DCF!$N$6+(DCF!$C$30-DCF!$C$31+DCF!$C$32))/DCF!$C$34 -> 784.39528 | I20: =(SUMPRODUCT(DCF!$E$11:$N$11,1/(1+I$19)^DCF!$E$7:$N$7)+Forecast!$Q$14*$B20/(1+I$19)^DCF!$N$6+(DCF!$C$30-DCF!$C$31+DCF!$C$32))/DCF!$C$34 -> 760.42128 | J20: =(SUMPRODUCT(DCF!$E$11:$N$11,1/(1+J$19)^DCF!$E$7:$N$7)+Forecast!$Q$14*$B20/(1+J$19)^DCF!$N$6+(DCF!$C$30-DCF!$C$31+DCF!$C$32))/DCF!$C$34 -> 737.44319 | K20: =(SUMPRODUCT(DCF!$E$11:$N$11,1/(1+K$19)^DCF!$E$7:$N$7)+Forecast!$Q$14*$B20/(1+K$19)^DCF!$N$6+(DCF!$C$30-DCF!$C$31+DCF!$C$32))/DCF!$C$34 -> 715.41386
B21: =$B$24+(-3)*$N$7 -> 14 | C21: =(SUMPRODUCT(DCF!$E$11:$N$11,1/(1+C$19)^DCF!$E$7:$N$7)+Forecast!$Q$14*$B21/(1+C$19)^DCF!$N$6+(DCF!$C$30-DCF!$C$31+DCF!$C$32))/DCF!$C$34 -> 1010.7021 | D21: =(SUMPRODUCT(DCF!$E$11:$N$11,1/(1+D$19)^DCF!$E$7:$N$7)+Forecast!$Q$14*$B21/(1+D$19)^DCF!$N$6+(DCF!$C$30-DCF!$C$31+DCF!$C$32))/DCF!$C$34 -> 977.17985 | E21: =(SUMPRODUCT(DCF!$E$11:$N$11,1/(1+E$19)^DCF!$E$7:$N$7)+Forecast!$Q$14*$B21/(1+E$19)^DCF!$N$6+(DCF!$C$30-DCF!$C$31+DCF!$C$32))/DCF!$C$34 -> 945.10613 | F21: =(SUMPRODUCT(DCF!$E$11:$N$11,1/(1+F$19)^DCF!$E$7:$N$7)+Forecast!$Q$14*$B21/(1+F$19)^DCF!$N$6+(DCF!$C$30-DCF!$C$31+DCF!$C$32))/DCF!$C$34 -> 914.41022 | G21: =(SUMPRODUCT(DCF!$E$11:$N$11,1/(1+G$19)^DCF!$E$7:$N$7)+Forecast!$Q$14*$B21/(1+G$19)^DCF!$N$6+(DCF!$C$30-DCF!$C$31+DCF!$C$32))/DCF!$C$34 -> 885.02518 | H21: =(SUMPRODUCT(DCF!$E$11:$N$11,1/(1+H$19)^DCF!$E$7:$N$7)+Forecast!$Q$14*$B21/(1+H$19)^DCF!$N$6+(DCF!$C$30-DCF!$C$31+DCF!$C$32))/DCF!$C$34 -> 856.88765 | I21: =(SUMPRODUCT(DCF!$E$11:$N$11,1/(1+I$19)^DCF!$E$7:$N$7)+Forecast!$Q$14*$B21/(1+I$19)^DCF!$N$6+(DCF!$C$30-DCF!$C$31+DCF!$C$32))/DCF!$C$34 -> 829.93766 | J21: =(SUMPRODUCT(DCF!$E$11:$N$11,1/(1+J$19)^DCF!$E$7:$N$7)+Forecast!$Q$14*$B21/(1+J$19)^DCF!$N$6+(DCF!$C$30-DCF!$C$31+DCF!$C$32))/DCF!$C$34 -> 804.11838 | K21: =(SUMPRODUCT(DCF!$E$11:$N$11,1/(1+K$19)^DCF!$E$7:$N$7)+Forecast!$Q$14*$B21/(1+K$19)^DCF!$N$6+(DCF!$C$30-DCF!$C$31+DCF!$C$32))/DCF!$C$34 -> 779.376
B22: =$B$24+(-2)*$N$7 -> 16 | C22: =(SUMPRODUCT(DCF!$E$11:$N$11,1/(1+C$19)^DCF!$E$7:$N$7)+Forecast!$Q$14*$B22/(1+C$19)^DCF!$N$6+(DCF!$C$30-DCF!$C$31+DCF!$C$32))/DCF!$C$34 -> 1100.358 | D22: =(SUMPRODUCT(DCF!$E$11:$N$11,1/(1+D$19)^DCF!$E$7:$N$7)+Forecast!$Q$14*$B22/(1+D$19)^DCF!$N$6+(DCF!$C$30-DCF!$C$31+DCF!$C$32))/DCF!$C$34 -> 1063.0715 | E22: =(SUMPRODUCT(DCF!$E$11:$N$11,1/(1+E$19)^DCF!$E$7:$N$7)+Forecast!$Q$14*$B22/(1+E$19)^DCF!$N$6+(DCF!$C$30-DCF!$C$31+DCF!$C$32))/DCF!$C$34 -> 1027.4079 | F22: =(SUMPRODUCT(DCF!$E$11:$N$11,1/(1+F$19)^DCF!$E$7:$N$7)+Forecast!$Q$14*$B22/(1+F$19)^DCF!$N$6+(DCF!$C$30-DCF!$C$31+DCF!$C$32))/DCF!$C$34 -> 993.2876 | G22: =(SUMPRODUCT(DCF!$E$11:$N$11,1/(1+G$19)^DCF!$E$7:$N$7)+Forecast!$Q$14*$B22/(1+G$19)^DCF!$N$6+(DCF!$C$30-DCF!$C$31+DCF!$C$32))/DCF!$C$34 -> 960.63539 | H22: =(SUMPRODUCT(DCF!$E$11:$N$11,1/(1+H$19)^DCF!$E$7:$N$7)+Forecast!$Q$14*$B22/(1+H$19)^DCF!$N$6+(DCF!$C$30-DCF!$C$31+DCF!$C$32))/DCF!$C$34 -> 929.38002 | I22: =(SUMPRODUCT(DCF!$E$11:$N$11,1/(1+I$19)^DCF!$E$7:$N$7)+Forecast!$Q$14*$B22/(1+I$19)^DCF!$N$6+(DCF!$C$30-DCF!$C$31+DCF!$C$32))/DCF!$C$34 -> 899.45404 | J22: =(SUMPRODUCT(DCF!$E$11:$N$11,1/(1+J$19)^DCF!$E$7:$N$7)+Forecast!$Q$14*$B22/(1+J$19)^DCF!$N$6+(DCF!$C$30-DCF!$C$31+DCF!$C$32))/DCF!$C$34 -> 870.79357 | K22: =(SUMPRODUCT(DCF!$E$11:$N$11,1/(1+K$19)^DCF!$E$7:$N$7)+Forecast!$Q$14*$B22/(1+K$19)^DCF!$N$6+(DCF!$C$30-DCF!$C$31+DCF!$C$32))/DCF!$C$34 -> 843.33813
